Workbook

Sheet Start Here
B2: TRADING JOURNAL SYSTEM
B3: A journal that teaches you HOW to journal — and does every calculation for you.
B5: SET UP IN 10 MINUTES
B6: 1. Settings tab → choose what you trade (Futures, Stocks, Options, Forex or Crypto). Then enter your real fees and your risk rules. The fees shown are examples.
B7: 2. Accounts tab → add each account you trade. Prop-firm traders: enter your firm's drawdown, daily limit, profit target and consistency rule.
B8: 3. Setup Playbook tab → replace the 4 example setups with the 2–4 setups you actually trade.
B9: 4. Clear the examples: Trade Log → select the WHITE cells in rows 6–33 and press Delete. Do the same for the sample notes on the Daily Journal and Weekly Review tabs, then type your own start dates in their B6 cells. Never delete rows or the grey columns.
B10: 5. Log your next trade. The grey columns, the Dashboard, the Daily Journal and the Weekly Review all fill in by themselves.
B12: THE SYSTEM — HOW TO ACTUALLY JOURNAL
B13: Most traders log trades and never learn from them. This system runs on three loops:
B14: EVERY TRADE (30 seconds). Log it right after you close it. Write your stop and target BEFORE you enter — your R is measured against them. Tag the setup, how you felt, and any mistake. Be honest on 'Followed rules?' — a losing trade can still be a Yes.
B15: EVERY DAY (5 minutes). Daily Journal tab: what the market did, what you did, and whether you'd repeat it or delete it. Grade your execution, not your P&L.
... B23: 5. Missed a day? Fill it in and keep going. Consistency beats perfection.
B25: ="YOUR MODE: "&UPPER(Settings!$C$6)&" (change it on the Settings tab)" -> YOUR MODE: FUTURES (change it on the Settings tab)
B26: =CHOOSE(IFERROR(MATCH(Settings!$C$6,{"Futures","Stocks","Options","Forex","Crypto"},0),1),"Qty = contracts. Point values come from the Instruments tab (micros and minis included), so P&L is exact per contract. Fees = per contract, per side.","Qty = shares. P&L = price change × shares. Fees = per share, per side (set 0 if your broker is commission-free).","Enter the option PREMIUM as Entry/Exit (e.g. 2.35) and Qty in contracts. Each contract = 100 shares. Fees = per contract, per side.","Qty = standard lots (0.10 = a mini lot). P&L converts automatically for pairs that include your account currency. For crosses like EURJPY on a USD account, type your broker's P&L in Gross P&L.","Qty = coins (e.g. 0.05 BTC), not dollars. Fees: maker % for Limit entries and Target exits, taker % otherwise. Fill in Leverage to track your max-leverage rule. Add funding fees in the Fees column.") -> Qty = contracts. Point values come from the Instruments tab (micros and minis included), so P&L is exact per contract. Fees = per contract, per side.
B28: FAQ & TROUBLESHOOTING
B29: Net P&L is blank → the symbol isn't on the Instruments tab for that market. Add it (with its point value) or type your broker's P&L in 'Gross P&L (broker)'.
B30: My P&L doesn't match my broker → type your broker's numbers in the two optional columns (Gross P&L and Fees). The sheet then uses yours.
B31: Rule check says something I didn't expect → it reads the rules on the Settings tab. Blank a rule there to switch that check off.
B32: Futures fees → set a default on Settings, or a per-symbol fee on the Instruments tab (micros usually cost less than minis).
B33: Requirements → Excel 2019 or newer, Microsoft 365, or Google Sheets (File → Import or open the file in Drive). Apple Numbers is not supported.
B34: Sorting → keep the Trade Log in time order (oldest at the top). Streaks and running balances read top to bottom.
B36: IMPORTANT
B37: Contract specs on the Instruments tab were checked against CME Group's published specifications in October 2026. Exchanges can change them — verify before relying on them.
B38: Prop-firm rules differ by firm and change often. The Accounts tracker uses closed trades only. Your firm's own dashboard is the final word.
B39: All fees, accounts and trades in this file are examples. This is a journaling tool, not financial advice.

Sheet Settings
B2: SETTINGS
B3: Set these once. Yellow cells are yours to change. Everything else in the journal reads from here.
B5: 1 · WHAT YOU TRADE — this is the mode switch
B6: What do you mainly trade? | C6: Futures | D6: Changes the Qty label, session list, symbol dropdown and default market. Each account on the Accounts tab can also have its own market, so mixed traders get correct math on every trade.
B7: Account currency (3 letters) | C7: USD | D7: Shown in P&L headers. Forex P&L converts automatically for pairs that include this currency.
B8: Scratch zone (± R) | C8: 0.1 | D8: Trades that close within ±0.10R count as scratches, not wins or losses.
B9: Journal name | C9: My Trading Journal | D9: Shows at the top of the Dashboard.
B10: Daily Journal includes weekends? | C10: No | D10: Yes for crypto traders. No skips Saturday and Sunday.
B12: 2 · MARKET DEFAULTS — sizes and fees for each market
B13: Market | C13: Qty means | D13: Multiplier (if no symbol match) | E13: Fee model | F13: Fee per unit, per side | G13: Maker fee % | H13: Taker fee % | I13: How it works
B14: Futures | C14: contracts | D14: per symbol | E14: Per unit | F14: 0.5 | I14: Point value per symbol comes from the Instruments tab. Fee = per contract, per side.
B15: Stocks | C15: shares | D15: 1 | E15: Per unit | F15: 0 | I15: Qty = shares. Fee = per share, per side (0 if your broker is commission-free).
B16: Options | C16: contracts x100 | D16: 100 | E16: Per unit | F16: 0.65 | I16: Entry/Exit = option premium (e.g. 2.35). Qty = contracts. 1 contract = 100 shares.
B17: Forex | C17: lots | D17: 100000 | E17: Per unit | F17: 3.5 | I17: Qty = lots. 1 standard lot = 100,000 units at most brokers - check yours. Fee = commission per lot, per side.
B18: Crypto | C18: coins | D18: 1 | E18: % of notional | G18: 0.0002 | H18: 0.0006 | I18: Qty = coins (0.05 BTC), not dollars. Maker % on Limit entries and Target exits; taker % on everything else.
B19: ⚠ The fees above are EXAMPLES, not any broker's real rates. Replace them with yours. Futures can also have a per-symbol fee on the Instruments tab (micros usually cost less than minis).
B21: 3 · YOUR RISK RULES — leave a cell blank to switch that check off
B22: Max risk per trade ($) | C22: 250 | D22: Flags any trade risking more than this. Risk = stop distance × size × point value.
B23: Max risk per trade (% of account) | C23: 0.01 | D23: Uses the account balance before the trade. Needs a starting balance on the Accounts tab.
B24: Max leverage (x) | C24: 20 | D24: For crypto/forex trades where you fill in Leverage.
B25: Max trades per day | C25: 4 | D25: Flags every trade after this number on the same day.
B26: Daily max loss ($) | C26: 400 | D26: Flags trades taken after the day's losses reached this (all accounts combined).
B27: Minimum planned R:R | C27: 1.5 | D27: Flags trades planned below this reward-to-risk.
B29: 4 · SESSION NAMES — rename them to match how you trade
B30: # | C30: Futures | D30: Stocks | E30: Options | F30: Forex | G30: Crypto
B31: 1 | C31: Overnight | D31: Pre-market | E31: Pre-market | F31: Sydney | G31: Asia
B32: 2 | C32: London | D32: Open | E32: Open | F32: Tokyo | G32: Europe
B33: 3 | C33: NY Open | D33: Morning | E33: Morning | F33: London | G33: US
B34: 4 | C34: NY Midday | D34: Midday | E34: Midday | F34: London/NY Overlap | G34: US Close
B35: 5 | C35: NY Afternoon | D35: Power Hour | E35: Power Hour | F35: New York | G35: Weekend
B36: 6 | C36: NY Close | D36: After-hours | E36: After-hours | F36: Late NY | G36: Overnight
B38: The Session dropdown in the Trade Log shows the column for your mode. You can still type any session name.

Sheet Trade Log
A1: TRADE LOG
A2: Log each trade right after you close it. White = you type · Grey = automatic. Keep trades in time order (oldest at the top). Hover over a header for help.
A3: Sample trades are in rows 6–33. When you're ready, select the WHITE cells in those rows and press Delete. Never delete rows or the grey columns.
A4: YOUR TRADE (type here) | Q4: RESULTS (automatic) | X4: REVIEW (type here) | AF4: HELPER COLUMNS (automatic — don't edit)
A5: Date | B5: Time | C5: Account | D5: Market (optional) | E5: Symbol | F5: Long / Short | G5: ="Qty ("&IFERROR(INDEX(Settings!$C$14:$C$18,MATCH(Settings!$C$6,Settings!$B$14:$B$18,0)),"units")&")" -> Qty (contracts) | H5: Entry price | I5: Stop loss (original) | J5: Target | K5: Exit price (avg) | L5: Entry order | M5: Exit reason | N5: Leverage (x) | O5: Gross P&L (broker) optional | P5: Fees (broker) optional | Q5: ="Net P&L ("&Settings!$C$7&")" -> Net P&L (USD) | R5: R multiple | S5: Result | T5: Planned R:R | U5: R short of target | V5: $ Risk | W5: Rule check | X5: Session | Y5: Setup | Z5: Followed rules? | AA5: Emotion | AB5: Mistake | AC5: Why I took it | AD5: Review note | AE5: Screenshot link | AF5: Market used | AG5: Point value | AH5: FX factor | AI5: Gross (calc) | AJ5: Fees (calc) | AK5: Gross used | AL5: Fees used | AM5: Valid | AN5: Week of | AO5: Weekday | AP5: Acct balance after | AQ5: Acct day net | AR5: Acct EOD balance | AS5: In dashboard filter | AT5: Cum P&L (filter) | AU5: Peak (filter) | AV5: Drawdown (filter) | AW5: Win streak | AX5: Loss streak | AY5: Filter trade # | AZ5: Chart X | BA5: First of day | BB5: Day net (filter) | BC5: Has R | BD5: $ short of target | BE5: Instrument row | BF5: Market row | BG5: Flags (raw) | BH5: Has net | BI5: Setup tagged | BJ5: Mistake tagged | BK5: Flagged | BL5: Chart Y | BM5: After max loss
A6: 46286 | B6: 0.40416667 | C6: Prop Eval 50K | E6: MNQ | F6: Long | G6: 2 | H6: 29640 | I6: 29610 | J6: 29700 | K6: 29700 | L6: Limit | M6: Target | Q6: =IF($AM6=0,"",IF(ISNUMBER($AK6),$AK6-N($AL6),"")) -> 238 | R6: =IF(OR($Q6="",NOT(ISNUMBER($V6))),"",$AK6/$V6) -> 2 | S6: =IF($Q6="","",IF(AND(ISNUMBER($R6),ABS(N($R6))<N(Settings!$C$8)),"Scratch",IF($Q6>0,"Win",IF($Q6<0,"Loss","Scratch")))) -> Win | T6: =IF(OR($AM6=0,NOT(ISNUMBER($H6)),NOT(ISNUMBER($I6)),NOT(ISNUMBER($J6))),"",IF($H6=$I6,"",ROUND(ABS($J6-$H6)/ABS($H6-$I6),6))) -> 2 | U6: =IF(OR($S6<>"Win",NOT(ISNUMBER($T6)),NOT(ISNUMBER($R6))),"",MAX(0,$T6-$R6)) -> 0 | V6: =IF(OR($AM6=0,NOT(ISNUMBER($H6)),NOT(ISNUMBER($I6)),NOT(ISNUMBER($G6))),"",IF(OR($AG6="",$AH6=""),"",IF(ROUND(ABS($H6-$I6)*ABS($G6)*$AG6*$AH6,6)=0,"",ROUND(ABS($H6-$I6)*ABS($G6)*$AG6*$AH6,6)))) -> 120 | W6: =IF($AM6=0,"",IF($BG6="","OK",LEFT($BG6,LEN($BG6)-2))) -> OK | X6: NY Open | Y6: Breakout & Retest | Z6: Yes | AA6: Calm | AC6: Retest of overnight high held on volume | AD6: Textbook. Held to target. | AF6: =IF($AM6=0,"",IF($D6<>"",$D6,IF(IFERROR(INDEX(Accounts!$C$7:$C$16,MATCH($C6,Accounts!$B$7:$B$16,0))&"","")<>"",INDEX(Accounts!$C$7:$C$16,MATCH($C6,Accounts!$B$7:$B$16,0)),Settings!$C$6))) -> Futures | AG6: =IF($AM6=0,"",IF(AND($BE6>0,N(INDEX(Instruments!$D$6:$D$205,MAX(1,$BE6)))>0),INDEX(Instruments!$D$6:$D$205,MAX(1,$BE6)),IF(N(INDEX(Settings!$D$14:$D$18,$BF6))>0,INDEX(Settings!$D$14:$D$18,$BF6),""))) -> 2 | AH6: =IF($AM6=0,"",IF($AF6<>"Forex",1,IF(MID(UPPER(SUBSTITUTE(TRIM($E6),"/","")),4,3)=UPPER(TRIM(Settings!$C$7)),1,IF(LEFT(UPPER(SUBSTITUTE(TRIM($E6),"/","")),3)=UPPER(TRIM(Settings!$C$7)),IF(AND(ISNUMBER($K6),N($K6)<>0),1/$K6,""),"")))) -> 1 | AI6: =IF($AM6=0,"",IF(OR(NOT(ISNUMBER($H6)),NOT(ISNUMBER($K6)),NOT(ISNUMBER($G6)),$AG6="",$AH6=""),"",ROUND(($K6-$H6)*IF($F6="Short",-1,1)*$G6*$AG6*$AH6,6))) -> 240 | AJ6: =IF($AM6=0,"",IF(INDEX(Settings!$E$14:$E$18,$BF6)="% of notional",IF(OR($AG6="",NOT(ISNUMBER($H6)),NOT(ISNUMBER($G6))),"",ROUND(ABS($H6*$G6*$AG6*N($AH6))*IF($L6="Limit",N(INDEX(Settings!$G$14:$G$18,$BF6)),N(INDEX(Settings!$H$14:$H$18,$BF6)))+IF(ISNUMBER($K6),ABS($K6*$G6*$AG6*N($AH6))*IF($M6="Target",N(INDEX(Settings!$G$14:$G$18,$BF6)),N(INDEX(Settings!$H$14:$H$18,$BF6))),0),6)),IF(NOT(ISNUMBER($G6)),"",ROUND(ABS($G6)*2*IF(AND($BE6>0,ISNUMBER(INDEX(Instruments!$G$6:$G$205,MAX(1,$BE6)))),INDEX(Instruments!$G$6:$G$205,MAX(1,$BE6)),N(INDEX(Settings!$F$14:$F$18,$BF6))),6)))) -> 2 | AK6: =IF($AM6=0,"",IF(ISNUMBER($O6),$O6,$AI6)) -> 240 | AL6: =IF($AM6=0,"",IF(ISNUMBER($P6),$P6,N($AJ6))) -> 2 | AM6: =IF(AND($A6<>"",$E6<>"",OR(AND(ISNUMBER($G6),ISNUMBER($H6),ISNUMBER($K6)),ISNUMBER($O6))),1,0) -> 1 | AN6: =IF($A6="","",$A6-WEEKDAY($A6,3)) -> 46286 | AO6: =IF($A6="","",WEEKDAY($A6,2)) -> 1 | AP6: =IF(OR($AM6=0,$C6=""),"",IFERROR(N(INDEX(Accounts!$E$7:$E$16,MATCH($C6,Accounts!$B$7:$B$16,0))),0)+SUMIFS($Q$6:$Q6,$C$6:$C6,$C6)) -> 50238 | AQ6: =IF(OR($AM6=0,$C6=""),"",SUMIFS($Q$6:$Q$1005,$C$6:$C$1005,$C6,$A$6:$A$1005,$A6)) -> 298.5 | AR6: =IF(OR($AM6=0,$C6=""),"",IFERROR(N(INDEX(Accounts!$E$7:$E$16,MATCH($C6,Accounts!$B$7:$B$16,0))),0)+SUMIFS($Q$6:$Q$1005,$C$6:$C$1005,$C6,$A$6:$A$1005,"<="&$A6)) -> 50298.5 | AS6: =IF(OR($AM6=0,$Q6=""),0,IF(AND($A6>=Lists!$W$6,$A6<=Lists!$W$7,OR(Dashboard!$D$6="All accounts",$C6=Dashboard!$D$6),OR(Dashboard!$D$7="All markets",$AF6=Dashboard!$D$7)),1,0)) -> 1 | AT6: =IF($AS6=1,N(AT5)+$Q6,N(AT5)) -> 238 | AU6: =MAX(N(AU5),$AT6) -> 238 | AV6: =$AT6-$AU6 -> 0 | AW6: =IF($AS6=1,IF($S6="Win",N(AW5)+1,IF($S6="Loss",0,N(AW5))),N(AW5)) -> 1 | AX6: =IF($AS6=1,IF($S6="Loss",N(AX5)+1,IF($S6="Win",0,N(AX5))),N(AX5)) -> 0 | AY6: =IF($AS6=1,COUNTIF($AS$6:$AS6,1),"") -> 1 | AZ6: =MIN(0,N(Lists!$W$8)) -> 0 | BA6: =IF($AS6=1,IF(COUNTIFS($A$6:$A6,$A6,$AS$6:$AS6,1)=1,1,0),0) -> 1 | BB6: =IF($BA6=1,SUMIFS($Q$6:$Q$1005,$A$6:$A$1005,$A6,$AS$6:$AS$1005,1),"") -> 298.5 | BC6: =IF(ISNUMBER($R6),1,0) -> 1 | BD6: =IF(ISNUMBER($U6),$U6*$V6,"") -> 0 | BE6: =IF($AM6=0,"",IFERROR(MATCH($AF6&"|"&UPPER(TRIM($E6)),Lists!$A$6:$A$205,0),0)) -> 3 | BF6: =IF($AM6=0,"",IFERROR(MATCH($AF6,Settings!$B$14:$B$18,0),IFERROR(MATCH(Settings!$C$6,Settings!$B$14:$B$18,0),1))) -> 1 | BG6: =IF($AM6=0,"",IF(NOT(ISNUMBER($I6)),"No stop; ","")&IF(AND(ISNUMBER($H6),ISNUMBER($I6)),IF(OR(AND($F6<>"Short",$I6>=$H6),AND($F6="Short",$I6<=$H6)),"Stop on wrong side; ",""),"")&IF($F6="","No direction; ","")&IF(AND(ISNUMBER(Settings!$C$22),ISNUMBER($V6)),IF($V6>Settings!$C$22,"Risk over max $; ",""),"")&IF(AND(ISNUMBER(Settings!$C$23),ISNUMBER($V6),ISNUMBER($AP6),IFERROR(N(INDEX(Accounts!$E$7:$E$16,MATCH($C6,Accounts!$B$7:$B$16,0))),0)>0),IF($V6>Settings!$C$23*($AP6-N($Q6)),"Risk over max %; ",""),"")&IF(AND(ISNUMBER(Settings!$C$24),ISNUMBER($N6)),IF($N6>Settings!$C$24,"Leverage over max; ",""),"")&IF(AND(ISNUMBER(Settings!$C$27),ISNUMBER($T6)),IF($T6<Settings!$C$27,"R:R below min; ",""),"")&IF(ISNUMBER(Settings!$C$25),IF(COUNTIFS($A$6:$A6,$A6,$AM$6:$AM6,1)>Settings!$C$25,"Over max trades/day; ",""),"")&IF(ISNUMBER(Settings!$C$26),IF(SUMIFS($Q$5:$Q5,$A$5:$A5,$A6)<=-Settings!$C$26,"Traded after daily max loss; ",""),"")&IF(AND($AG6="",NOT(ISNUMBER($O6))),"Symbol not in Instruments; ","")&IF(AND($AH6="",NOT(ISNUMBER($O6))),"Forex cross: type Gross P&L; ","")) | BH6: =IF(ISNUMBER($Q6),1,0) -> 1 | BI6: =IF($Y6="",0,1) -> 1 | BJ6: =IF($AB6="",0,1) -> 0 | BK6: =IF(AND($BH6=1,$W6<>"OK"),1,0) -> 0 | BL6: =IF(N($AZ6)=0,0,IFERROR(INDEX($AT$6:$AT$1005,MATCH($AZ6,$AY$6:$AY$1005,0)),0)) -> 0 | BM6: =IF(ISNUMBER(SEARCH("daily max loss",$BG6)),1,0) -> 0
A7: 46286 | B7: 0.43819444 | C7: Prop Eval 50K | E7: MES | F7: Long | G7: 2 | H7: 7662.5 | I7: 7655 | J7: 7677.5 | K7: 7668.75 | L7: Limit | M7: Manual | Q7: =IF($AM7=0,"",IF(ISNUMBER($AK7),$AK7-N($AL7),"")) -> 60.5 | R7: =IF(OR($Q7="",NOT(ISNUMBER($V7))),"",$AK7/$V7) -> 0.83333333 | S7: =IF($Q7="","",IF(AND(ISNUMBER($R7),ABS(N($R7))<N(Settings!$C$8)),"Scratch",IF($Q7>0,"Win",IF($Q7<0,"Loss","Scratch")))) -> Win | T7: =IF(OR($AM7=0,NOT(ISNUMBER($H7)),NOT(ISNUMBER($I7)),NOT(ISNUMBER($J7))),"",IF($H7=$I7,"",ROUND(ABS($J7-$H7)/ABS($H7-$I7),6))) -> 2 | U7: =IF(OR($S7<>"Win",NOT(ISNUMBER($T7)),NOT(ISNUMBER($R7))),"",MAX(0,$T7-$R7)) -> 1.1666667 | V7: =IF(OR($AM7=0,NOT(ISNUMBER($H7)),NOT(ISNUMBER($I7)),NOT(ISNUMBER($G7))),"",IF(OR($AG7="",$AH7=""),"",IF(ROUND(ABS($H7-$I7)*ABS($G7)*$AG7*$AH7,6)=0,"",ROUND(ABS($H7-$I7)*ABS($G7)*$AG7*$AH7,6)))) -> 75 | W7: =IF($AM7=0,"",IF($BG7="","OK",LEFT($BG7,LEN($BG7)-2))) -> OK | X7: NY Open | Y7: Trend Pullback | Z7: No | AA7: Hesitant | AB7: Took profit too early | AC7: Pullback to 20 EMA in an uptrend | AD7: Got nervous at the prior high and bailed early. | AF7: =IF($AM7=0,"",IF($D7<>"",$D7,IF(IFERROR(INDEX(Accounts!$C$7:$C$16,MATCH($C7,Accounts!$B$7:$B$16,0))&"","")<>"",INDEX(Accounts!$C$7:$C$16,MATCH($C7,Accounts!$B$7:$B$16,0)),Settings!$C$6))) -> Futures | AG7: =IF($AM7=0,"",IF(AND($BE7>0,N(INDEX(Instruments!$D$6:$D$205,MAX(1,$BE7)))>0),INDEX(Instruments!$D$6:$D$205,MAX(1,$BE7)),IF(N(INDEX(Settings!$D$14:$D$18,$BF7))>0,INDEX(Settings!$D$14:$D$18,$BF7),""))) -> 5 | AH7: =IF($AM7=0,"",IF($AF7<>"Forex",1,IF(MID(UPPER(SUBSTITUTE(TRIM($E7),"/","")),4,3)=UPPER(TRIM(Settings!$C$7)),1,IF(LEFT(UPPER(SUBSTITUTE(TRIM($E7),"/","")),3)=UPPER(TRIM(Settings!$C$7)),IF(AND(ISNUMBER($K7),N($K7)<>0),1/$K7,""),"")))) -> 1 | AI7: =IF($AM7=0,"",IF(OR(NOT(ISNUMBER($H7)),NOT(ISNUMBER($K7)),NOT(ISNUMBER($G7)),$AG7="",$AH7=""),"",ROUND(($K7-$H7)*IF($F7="Short",-1,1)*$G7*$AG7*$AH7,6))) -> 62.5 | AJ7: =IF($AM7=0,"",IF(INDEX(Settings!$E$14:$E$18,$BF7)="% of notional",IF(OR($AG7="",NOT(ISNUMBER($H7)),NOT(ISNUMBER($G7))),"",ROUND(ABS($H7*$G7*$AG7*N($AH7))*IF($L7="Limit",N(INDEX(Settings!$G$14:$G$18,$BF7)),N(INDEX(Settings!$H$14:$H$18,$BF7)))+IF(ISNUMBER($K7),ABS($K7*$G7*$AG7*N($AH7))*IF($M7="Target",N(INDEX(Settings!$G$14:$G$18,$BF7)),N(INDEX(Settings!$H$14:$H$18,$BF7))),0),6)),IF(NOT(ISNUMBER($G7)),"",ROUND(ABS($G7)*2*IF(AND($BE7>0,ISNUMBER(INDEX(Instruments!$G$6:$G$205,MAX(1,$BE7)))),INDEX(Instruments!$G$6:$G$205,MAX(1,$BE7)),N(INDEX(Settings!$F$14:$F$18,$BF7))),6)))) -> 2 | AK7: =IF($AM7=0,"",IF(ISNUMBER($O7),$O7,$AI7)) -> 62.5 | AL7: =IF($AM7=0,"",IF(ISNUMBER($P7),$P7,N($AJ7))) -> 2 | AM7: =IF(AND($A7<>"",$E7<>"",OR(AND(ISNUMBER($G7),ISNUMBER($H7),ISNUMBER($K7)),ISNUMBER($O7))),1,0) -> 1 | AN7: =IF($A7="","",$A7-WEEKDAY($A7,3)) -> 46286 | AO7: =IF($A7="","",WEEKDAY($A7,2)) -> 1 | AP7: =IF(OR($AM7=0,$C7=""),"",IFERROR(N(INDEX(Accounts!$E$7:$E$16,MATCH($C7,Accounts!$B$7:$B$16,0))),0)+SUMIFS($Q$6:$Q7,$C$6:$C7,$C7)) -> 50298.5 | AQ7: =IF(OR($AM7=0,$C7=""),"",SUMIFS($Q$6:$Q$1005,$C$6:$C$1005,$C7,$A$6:$A$1005,$A7)) -> 298.5 | AR7: =IF(OR($AM7=0,$C7=""),"",IFERROR(N(INDEX(Accounts!$E$7:$E$16,MATCH($C7,Accounts!$B$7:$B$16,0))),0)+SUMIFS($Q$6:$Q$1005,$C$6:$C$1005,$C7,$A$6:$A$1005,"<="&$A7)) -> 50298.5 | AS7: =IF(OR($AM7=0,$Q7=""),0,IF(AND($A7>=Lists!$W$6,$A7<=Lists!$W$7,OR(Dashboard!$D$6="All accounts",$C7=Dashboard!$D$6),OR(Dashboard!$D$7="All markets",$AF7=Dashboard!$D$7)),1,0)) -> 1 | AT7: =IF($AS7=1,N(AT6)+$Q7,N(AT6)) -> 298.5 | AU7: =MAX(N(AU6),$AT7) -> 298.5 | AV7: =$AT7-$AU7 -> 0 | AW7: =IF($AS7=1,IF($S7="Win",N(AW6)+1,IF($S7="Loss",0,N(AW6))),N(AW6)) -> 2 | AX7: =IF($AS7=1,IF($S7="Loss",N(AX6)+1,IF($S7="Win",0,N(AX6))),N(AX6)) -> 0 | AY7: =IF($AS7=1,COUNTIF($AS$6:$AS7,1),"") -> 2 | AZ7: =MIN(1,N(Lists!$W$8)) -> 1 | BA7: =IF($AS7=1,IF(COUNTIFS($A$6:$A7,$A7,$AS$6:$AS7,1)=1,1,0),0) -> 0 | BB7: =IF($BA7=1,SUMIFS($Q$6:$Q$1005,$A$6:$A$1005,$A7,$AS$6:$AS$1005,1),"") | BC7: =IF(ISNUMBER($R7),1,0) -> 1 | BD7: =IF(ISNUMBER($U7),$U7*$V7,"") -> 87.5 | BE7: =IF($AM7=0,"",IFERROR(MATCH($AF7&"|"&UPPER(TRIM($E7)),Lists!$A$6:$A$205,0),0)) -> 1 | BF7: =IF($AM7=0,"",IFERROR(MATCH($AF7,Settings!$B$14:$B$18,0),IFERROR(MATCH(Settings!$C$6,Settings!$B$14:$B$18,0),1))) -> 1 | BG7: =IF($AM7=0,"",IF(NOT(ISNUMBER($I7)),"No stop; ","")&IF(AND(ISNUMBER($H7),ISNUMBER($I7)),IF(OR(AND($F7<>"Short",$I7>=$H7),AND($F7="Short",$I7<=$H7)),"Stop on wrong side; ",""),"")&IF($F7="","No direction; ","")&IF(AND(ISNUMBER(Settings!$C$22),ISNUMBER($V7)),IF($V7>Settings!$C$22,"Risk over max $; ",""),"")&IF(AND(ISNUMBER(Settings!$C$23),ISNUMBER($V7),ISNUMBER($AP7),IFERROR(N(INDEX(Accounts!$E$7:$E$16,MATCH($C7,Accounts!$B$7:$B$16,0))),0)>0),IF($V7>Settings!$C$23*($AP7-N($Q7)),"Risk over max %; ",""),"")&IF(AND(ISNUMBER(Settings!$C$24),ISNUMBER($N7)),IF($N7>Settings!$C$24,"Leverage over max; ",""),"")&IF(AND(ISNUMBER(Settings!$C$27),ISNUMBER($T7)),IF($T7<Settings!$C$27,"R:R below min; ",""),"")&IF(ISNUMBER(Settings!$C$25),IF(COUNTIFS($A$6:$A7,$A7,$AM$6:$AM7,1)>Settings!$C$25,"Over max trades/day; ",""),"")&IF(ISNUMBER(Settings!$C$26),IF(SUMIFS($Q$5:$Q6,$A$5:$A6,$A7)<=-Settings!$C$26,"Traded after daily max loss; ",""),"")&IF(AND($AG7="",NOT(ISNUMBER($O7))),"Symbol not in Instruments; ","")&IF(AND($AH7="",NOT(ISNUMBER($O7))),"Forex cross: type Gross P&L; ","")) | BH7: =IF(ISNUMBER($Q7),1,0) -> 1 | BI7: =IF($Y7="",0,1) -> 1 | BJ7: =IF($AB7="",0,1) -> 1 | BK7: =IF(AND($BH7=1,$W7<>"OK"),1,0) -> 0 | BL7: =IF(N($AZ7)=0,0,IFERROR(INDEX($AT$6:$AT$1005,MATCH($AZ7,$AY$6:$AY$1005,0)),0)) -> 238 | BM7: =IF(ISNUMBER(SEARCH("daily max loss",$BG7)),1,0) -> 0
A8: 46287 | B8: 0.4 | C8: Prop Eval 50K | E8: MGC | F8: Long | G8: 1 | H8: 4052 | I8: 4046 | J8: 4064 | K8: 4064 | L8: Limit | M8: Target | Q8: =IF($AM8=0,"",IF(ISNUMBER($AK8),$AK8-N($AL8),"")) -> 119 | R8: =IF(OR($Q8="",NOT(ISNUMBER($V8))),"",$AK8/$V8) -> 2 | S8: =IF($Q8="","",IF(AND(ISNUMBER($R8),ABS(N($R8))<N(Settings!$C$8)),"Scratch",IF($Q8>0,"Win",IF($Q8<0,"Loss","Scratch")))) -> Win | T8: =IF(OR($AM8=0,NOT(ISNUMBER($H8)),NOT(ISNUMBER($I8)),NOT(ISNUMBER($J8))),"",IF($H8=$I8,"",ROUND(ABS($J8-$H8)/ABS($H8-$I8),6))) -> 2 | U8: =IF(OR($S8<>"Win",NOT(ISNUMBER($T8)),NOT(ISNUMBER($R8))),"",MAX(0,$T8-$R8)) -> 0 | V8: =IF(OR($AM8=0,NOT(ISNUMBER($H8)),NOT(ISNUMBER($I8)),NOT(ISNUMBER($G8))),"",IF(OR($AG8="",$AH8=""),"",IF(ROUND(ABS($H8-$I8)*ABS($G8)*$AG8*$AH8,6)=0,"",ROUND(ABS($H8-$I8)*ABS($G8)*$AG8*$AH8,6)))) -> 60 | W8: =IF($AM8=0,"",IF($BG8="","OK",LEFT($BG8,LEN($BG8)-2))) -> OK | X8: NY Open | Y8: Breakout & Retest | Z8: Yes | AA8: Calm | AC8: Gold held its breakout above the Asia high | AD8: Clean. | AF8: =IF($AM8=0,"",IF($D8<>"",$D8,IF(IFERROR(INDEX(Accounts!$C$7:$C$16,MATCH($C8,Accounts!$B$7:$B$16,0))&"","")<>"",INDEX(Accounts!$C$7:$C$16,MATCH($C8,Accounts!$B$7:$B$16,0)),Settings!$C$6))) -> Futures | AG8: =IF($AM8=0,"",IF(AND($BE8>0,N(INDEX(Instruments!$D$6:$D$205,MAX(1,$BE8)))>0),INDEX(Instruments!$D$6:$D$205,MAX(1,$BE8)),IF(N(INDEX(Settings!$D$14:$D$18,$BF8))>0,INDEX(Settings!$D$14:$D$18,$BF8),""))) -> 10 | AH8: =IF($AM8=0,"",IF($AF8<>"Forex",1,IF(MID(UPPER(SUBSTITUTE(TRIM($E8),"/","")),4,3)=UPPER(TRIM(Settings!$C$7)),1,IF(LEFT(UPPER(SUBSTITUTE(TRIM($E8),"/","")),3)=UPPER(TRIM(Settings!$C$7)),IF(AND(ISNUMBER($K8),N($K8)<>0),1/$K8,""),"")))) -> 1 | AI8: =IF($AM8=0,"",IF(OR(NOT(ISNUMBER($H8)),NOT(ISNUMBER($K8)),NOT(ISNUMBER($G8)),$AG8="",$AH8=""),"",ROUND(($K8-$H8)*IF($F8="Short",-1,1)*$G8*$AG8*$AH8,6))) -> 120 | AJ8: =IF($AM8=0,"",IF(INDEX(Settings!$E$14:$E$18,$BF8)="% of notional",IF(OR($AG8="",NOT(ISNUMBER($H8)),NOT(ISNUMBER($G8))),"",ROUND(ABS($H8*$G8*$AG8*N($AH8))*IF($L8="Limit",N(INDEX(Settings!$G$14:$G$18,$BF8)),N(INDEX(Settings!$H$14:$H$18,$BF8)))+IF(ISNUMBER($K8),ABS($K8*$G8*$AG8*N($AH8))*IF($M8="Target",N(INDEX(Settings!$G$14:$G$18,$BF8)),N(INDEX(Settings!$H$14:$H$18,$BF8))),0),6)),IF(NOT(ISNUMBER($G8)),"",ROUND(ABS($G8)*2*IF(AND($BE8>0,ISNUMBER(INDEX(Instruments!$G$6:$G$205,MAX(1,$BE8)))),INDEX(Instruments!$G$6:$G$205,MAX(1,$BE8)),N(INDEX(Settings!$F$14:$F$18,$BF8))),6)))) -> 1 | AK8: =IF($AM8=0,"",IF(ISNUMBER($O8),$O8,$AI8)) -> 120 | AL8: =IF($AM8=0,"",IF(ISNUMBER($P8),$P8,N($AJ8))) -> 1 | AM8: =IF(AND($A8<>"",$E8<>"",OR(AND(ISNUMBER($G8),ISNUMBER($H8),ISNUMBER($K8)),ISNUMBER($O8))),1,0) -> 1 | AN8: =IF($A8="","",$A8-WEEKDAY($A8,3)) -> 46286 | AO8: =IF($A8="","",WEEKDAY($A8,2)) -> 2 | AP8: =IF(OR($AM8=0,$C8=""),"",IFERROR(N(INDEX(Accounts!$E$7:$E$16,MATCH($C8,Accounts!$B$7:$B$16,0))),0)+SUMIFS($Q$6:$Q8,$C$6:$C8,$C8)) -> 50417.5 | AQ8: =IF(OR($AM8=0,$C8=""),"",SUMIFS($Q$6:$Q$1005,$C$6:$C$1005,$C8,$A$6:$A$1005,$A8)) -> 57 | AR8: =IF(OR($AM8=0,$C8=""),"",IFERROR(N(INDEX(Accounts!$E$7:$E$16,MATCH($C8,Accounts!$B$7:$B$16,0))),0)+SUMIFS($Q$6:$Q$1005,$C$6:$C$1005,$C8,$A$6:$A$1005,"<="&$A8)) -> 50355.5 | AS8: =IF(OR($AM8=0,$Q8=""),0,IF(AND($A8>=Lists!$W$6,$A8<=Lists!$W$7,OR(Dashboard!$D$6="All accounts",$C8=Dashboard!$D$6),OR(Dashboard!$D$7="All markets",$AF8=Dashboard!$D$7)),1,0)) -> 1 | AT8: =IF($AS8=1,N(AT7)+$Q8,N(AT7)) -> 417.5 | AU8: =MAX(N(AU7),$AT8) -> 417.5 | AV8: =$AT8-$AU8 -> 0 | AW8: =IF($AS8=1,IF($S8="Win",N(AW7)+1,IF($S8="Loss",0,N(AW7))),N(AW7)) -> 3 | AX8: =IF($AS8=1,IF($S8="Loss",N(AX7)+1,IF($S8="Win",0,N(AX7))),N(AX7)) -> 0 | AY8: =IF($AS8=1,COUNTIF($AS$6:$AS8,1),"") -> 3 | AZ8: =MIN(2,N(Lists!$W$8)) -> 2 | BA8: =IF($AS8=1,IF(COUNTIFS($A$6:$A8,$A8,$AS$6:$AS8,1)=1,1,0),0) -> 1 | BB8: =IF($BA8=1,SUMIFS($Q$6:$Q$1005,$A$6:$A$1005,$A8,$AS$6:$AS$1005,1),"") -> 115.704 | BC8: =IF(ISNUMBER($R8),1,0) -> 1 | BD8: =IF(ISNUMBER($U8),$U8*$V8,"") -> 0 | BE8: =IF($AM8=0,"",IFERROR(MATCH($AF8&"|"&UPPER(TRIM($E8)),Lists!$A$6:$A$205,0),0)) -> 14 | BF8: =IF($AM8=0,"",IFERROR(MATCH($AF8,Settings!$B$14:$B$18,0),IFERROR(MATCH(Settings!$C$6,Settings!$B$14:$B$18,0),1))) -> 1 | BG8: =IF($AM8=0,"",IF(NOT(ISNUMBER($I8)),"No stop; ","")&IF(AND(ISNUMBER($H8),ISNUMBER($I8)),IF(OR(AND($F8<>"Short",$I8>=$H8),AND($F8="Short",$I8<=$H8)),"Stop on wrong side; ",""),"")&IF($F8="","No direction; ","")&IF(AND(ISNUMBER(Settings!$C$22),ISNUMBER($V8)),IF($V8>Settings!$C$22,"Risk over max $; ",""),"")&IF(AND(ISNUMBER(Settings!$C$23),ISNUMBER($V8),ISNUMBER($AP8),IFERROR(N(INDEX(Accounts!$E$7:$E$16,MATCH($C8,Accounts!$B$7:$B$16,0))),0)>0),IF($V8>Settings!$C$23*($AP8-N($Q8)),"Risk over max %; ",""),"")&IF(AND(ISNUMBER(Settings!$C$24),ISNUMBER($N8)),IF($N8>Settings!$C$24,"Leverage over max; ",""),"")&IF(AND(ISNUMBER(Settings!$C$27),ISNUMBER($T8)),IF($T8<Settings!$C$27,"R:R below min; ",""),"")&IF(ISNUMBER(Settings!$C$25),IF(COUNTIFS($A$6:$A8,$A8,$AM$6:$AM8,1)>Settings!$C$25,"Over max trades/day; ",""),"")&IF(ISNUMBER(Settings!$C$26),IF(SUMIFS($Q$5:$Q7,$A$5:$A7,$A8)<=-Settings!$C$26,"Traded after daily max loss; ",""),"")&IF(AND($AG8="",NOT(ISNUMBER($O8))),"Symbol not in Instruments; ","")&IF(AND($AH8="",NOT(ISNUMBER($O8))),"Forex cross: type Gross P&L; ","")) | BH8: =IF(ISNUMBER($Q8),1,0) -> 1 | BI8: =IF($Y8="",0,1) -> 1 | BJ8: =IF($AB8="",0,1) -> 0 | BK8: =IF(AND($BH8=1,$W8<>"OK"),1,0) -> 0 | BL8: =IF(N($AZ8)=0,0,IFERROR(INDEX($AT$6:$AT$1005,MATCH($AZ8,$AY$6:$AY$1005,0)),0)) -> 298.5 | BM8: =IF(ISNUMBER(SEARCH("daily max loss",$BG8)),1,0) -> 0
A9: 46287 | B9: 0.46875 | C9: Prop Eval 50K | E9: MCL | F9: Short | G9: 2 | H9: 69.85 | I9: 70.15 | J9: 69.25 | K9: 70.15 | L9: Market | M9: Stop loss | Q9: =IF($AM9=0,"",IF(ISNUMBER($AK9),$AK9-N($AL9),"")) -> -62 | R9: =IF(OR($Q9="",NOT(ISNUMBER($V9))),"",$AK9/$V9) -> -1 | S9: =IF($Q9="","",IF(AND(ISNUMBER($R9),ABS(N($R9))<N(Settings!$C$8)),"Scratch",IF($Q9>0,"Win",IF($Q9<0,"Loss","Scratch")))) -> Loss | T9: =IF(OR($AM9=0,NOT(ISNUMBER($H9)),NOT(ISNUMBER($I9)),NOT(ISNUMBER($J9))),"",IF($H9=$I9,"",ROUND(ABS($J9-$H9)/ABS($H9-$I9),6))) -> 2 | U9: =IF(OR($S9<>"Win",NOT(ISNUMBER($T9)),NOT(ISNUMBER($R9))),"",MAX(0,$T9-$R9)) | V9: =IF(OR($AM9=0,NOT(ISNUMBER($H9)),NOT(ISNUMBER($I9)),NOT(ISNUMBER($G9))),"",IF(OR($AG9="",$AH9=""),"",IF(ROUND(ABS($H9-$I9)*ABS($G9)*$AG9*$AH9,6)=0,"",ROUND(ABS($H9-$I9)*ABS($G9)*$AG9*$AH9,6)))) -> 60 | W9: =IF($AM9=0,"",IF($BG9="","OK",LEFT($BG9,LEN($BG9)-2))) -> OK | X9: NY Midday | Y9: Failed Breakout Reversal | Z9: No | AA9: FOMO | AB9: Late entry (chased) | AC9: Chased the rejection after it already dropped | AD9: Late fill made the stop too tight. | AF9: =IF($AM9=0,"",IF($D9<>"",$D9,IF(IFERROR(INDEX(Accounts!$C$7:$C$16,MATCH($C9,Accounts!$B$7:$B$16,0))&"","")<>"",INDEX(Accounts!$C$7:$C$16,MATCH($C9,Accounts!$B$7:$B$16,0)),Settings!$C$6))) -> Futures | AG9: =IF($AM9=0,"",IF(AND($BE9>0,N(INDEX(Instruments!$D$6:$D$205,MAX(1,$BE9)))>0),INDEX(Instruments!$D$6:$D$205,MAX(1,$BE9)),IF(N(INDEX(Settings!$D$14:$D$18,$BF9))>0,INDEX(Settings!$D$14:$D$18,$BF9),""))) -> 100 | AH9: =IF($AM9=0,"",IF($AF9<>"Forex",1,IF(MID(UPPER(SUBSTITUTE(TRIM($E9),"/","")),4,3)=UPPER(TRIM(Settings!$C$7)),1,IF(LEFT(UPPER(SUBSTITUTE(TRIM($E9),"/","")),3)=UPPER(TRIM(Settings!$C$7)),IF(AND(ISNUMBER($K9),N($K9)<>0),1/$K9,""),"")))) -> 1 | AI9: =IF($AM9=0,"",IF(OR(NOT(ISNUMBER($H9)),NOT(ISNUMBER($K9)),NOT(ISNUMBER($G9)),$AG9="",$AH9=""),"",ROUND(($K9-$H9)*IF($F9="Short",-1,1)*$G9*$AG9*$AH9,6))) -> -60 | AJ9: =IF($AM9=0,"",IF(INDEX(Settings!$E$14:$E$18,$BF9)="% of notional",IF(OR($AG9="",NOT(ISNUMBER($H9)),NOT(ISNUMBER($G9))),"",ROUND(ABS($H9*$G9*$AG9*N($AH9))*IF($L9="Limit",N(INDEX(Settings!$G$14:$G$18,$BF9)),N(INDEX(Settings!$H$14:$H$18,$BF9)))+IF(ISNUMBER($K9),ABS($K9*$G9*$AG9*N($AH9))*IF($M9="Target",N(INDEX(Settings!$G$14:$G$18,$BF9)),N(INDEX(Settings!$H$14:$H$18,$BF9))),0),6)),IF(NOT(ISNUMBER($G9)),"",ROUND(ABS($G9)*2*IF(AND($BE9>0,ISNUMBER(INDEX(Instruments!$G$6:$G$205,MAX(1,$BE9)))),INDEX(Instruments!$G$6:$G$205,MAX(1,$BE9)),N(INDEX(Settings!$F$14:$F$18,$BF9))),6)))) -> 2 | AK9: =IF($AM9=0,"",IF(ISNUMBER($O9),$O9,$AI9)) -> -60 | AL9: =IF($AM9=0,"",IF(ISNUMBER($P9),$P9,N($AJ9))) -> 2 | AM9: =IF(AND($A9<>"",$E9<>"",OR(AND(ISNUMBER($G9),ISNUMBER($H9),ISNUMBER($K9)),ISNUMBER($O9))),1,0) -> 1 | AN9: =IF($A9="","",$A9-WEEKDAY($A9,3)) -> 46286 | AO9: =IF($A9="","",WEEKDAY($A9,2)) -> 2 | AP9: =IF(OR($AM9=0,$C9=""),"",IFERROR(N(INDEX(Accounts!$E$7:$E$16,MATCH($C9,Accounts!$B$7:$B$16,0))),0)+SUMIFS($Q$6:$Q9,$C$6:$C9,$C9)) -> 50355.5 | AQ9: =IF(OR($AM9=0,$C9=""),"",SUMIFS($Q$6:$Q$1005,$C$6:$C$1005,$C9,$A$6:$A$1005,$A9)) -> 57 | AR9: =IF(OR($AM9=0,$C9=""),"",IFERROR(N(INDEX(Accounts!$E$7:$E$16,MATCH($C9,Accounts!$B$7:$B$16,0))),0)+SUMIFS($Q$6:$Q$1005,$C$6:$C$1005,$C9,$A$6:$A$1005,"<="&$A9)) -> 50355.5 | AS9: =IF(OR($AM9=0,$Q9=""),0,IF(AND($A9>=Lists!$W$6,$A9<=Lists!$W$7,OR(Dashboard!$D$6="All accounts",$C9=Dashboard!$D$6),OR(Dashboard!$D$7="All markets",$AF9=Dashboard!$D$7)),1,0)) -> 1 | AT9: =IF($AS9=1,N(AT8)+$Q9,N(AT8)) -> 355.5 | AU9: =MAX(N(AU8),$AT9) -> 417.5 | AV9: =$AT9-$AU9 -> -62 | AW9: =IF($AS9=1,IF($S9="Win",N(AW8)+1,IF($S9="Loss",0,N(AW8))),N(AW8)) -> 0 | AX9: =IF($AS9=1,IF($S9="Loss",N(AX8)+1,IF($S9="Win",0,N(AX8))),N(AX8)) -> 1 | AY9: =IF($AS9=1,COUNTIF($AS$6:$AS9,1),"") -> 4 | AZ9: =MIN(3,N(Lists!$W$8)) -> 3 | BA9: =IF($AS9=1,IF(COUNTIFS($A$6:$A9,$A9,$AS$6:$AS9,1)=1,1,0),0) -> 0 | BB9: =IF($BA9=1,SUMIFS($Q$6:$Q$1005,$A$6:$A$1005,$A9,$AS$6:$AS$1005,1),"") | BC9: =IF(ISNUMBER($R9),1,0) -> 1 | BD9: =IF(ISNUMBER($U9),$U9*$V9,"") | BE9: =IF($AM9=0,"",IFERROR(MATCH($AF9&"|"&UPPER(TRIM($E9)),Lists!$A$6:$A$205,0),0)) -> 9 | BF9: =IF($AM9=0,"",IFERROR(MATCH($AF9,Settings!$B$14:$B$18,0),IFERROR(MATCH(Settings!$C$6,Settings!$B$14:$B$18,0),1))) -> 1 | BG9: =IF($AM9=0,"",IF(NOT(ISNUMBER($I9)),"No stop; ","")&IF(AND(ISNUMBER($H9),ISNUMBER($I9)),IF(OR(AND($F9<>"Short",$I9>=$H9),AND($F9="Short",$I9<=$H9)),"Stop on wrong side; ",""),"")&IF($F9="","No direction; ","")&IF(AND(ISNUMBER(Settings!$C$22),ISNUMBER($V9)),IF($V9>Settings!$C$22,"Risk over max $; ",""),"")&IF(AND(ISNUMBER(Settings!$C$23),ISNUMBER($V9),ISNUMBER($AP9),IFERROR(N(INDEX(Accounts!$E$7:$E$16,MATCH($C9,Accounts!$B$7:$B$16,0))),0)>0),IF($V9>Settings!$C$23*($AP9-N($Q9)),"Risk over max %; ",""),"")&IF(AND(ISNUMBER(Settings!$C$24),ISNUMBER($N9)),IF($N9>Settings!$C$24,"Leverage over max; ",""),"")&IF(AND(ISNUMBER(Settings!$C$27),ISNUMBER($T9)),IF($T9<Settings!$C$27,"R:R below min; ",""),"")&IF(ISNUMBER(Settings!$C$25),IF(COUNTIFS($A$6:$A9,$A9,$AM$6:$AM9,1)>Settings!$C$25,"Over max trades/day; ",""),"")&IF(ISNUMBER(Settings!$C$26),IF(SUMIFS($Q$5:$Q8,$A$5:$A8,$A9)<=-Settings!$C$26,"Traded after daily max loss; ",""),"")&IF(AND($AG9="",NOT(ISNUMBER($O9))),"Symbol not in Instruments; ","")&IF(AND($AH9="",NOT(ISNUMBER($O9))),"Forex cross: type Gross P&L; ","")) | BH9: =IF(ISNUMBER($Q9),1,0) -> 1 | BI9: =IF($Y9="",0,1) -> 1 | BJ9: =IF($AB9="",0,1) -> 1 | BK9: =IF(AND($BH9=1,$W9<>"OK"),1,0) -> 0 | BL9: =IF(N($AZ9)=0,0,IFERROR(INDEX($AT$6:$AT$1005,MATCH($AZ9,$AY$6:$AY$1005,0)),0)) -> 417.5 | BM9: =IF(ISNUMBER(SEARCH("daily max loss",$BG9)),1,0) -> 0
A10: 46287 | B10: 0.88541667 | C10: Crypto Main | E10: BTCUSDT | F10: Long | G10: 0.05 | H10: 64200 | I10: 63600 | J10: 65400 | K10: 65400 | L10: Limit | M10: Target | N10: 10 | Q10: =IF($AM10=0,"",IF(ISNUMBER($AK10),$AK10-N($AL10),"")) -> 58.704 | R10: =IF(OR($Q10="",NOT(ISNUMBER($V10))),"",$AK10/$V10) -> 2 | S10: =IF($Q10="","",IF(AND(ISNUMBER($R10),ABS(N($R10))<N(Settings!$C$8)),"Scratch",IF($Q10>0,"Win",IF($Q10<0,"Loss","Scratch")))) -> Win | T10: =IF(OR($AM10=0,NOT(ISNUMBER($H10)),NOT(ISNUMBER($I10)),NOT(ISNUMBER($J10))),"",IF($H10=$I10,"",ROUND(ABS($J10-$H10)/ABS($H10-$I10),6))) -> 2 | U10: =IF(OR($S10<>"Win",NOT(ISNUMBER($T10)),NOT(ISNUMBER($R10))),"",MAX(0,$T10-$R10)) -> 0 | V10: =IF(OR($AM10=0,NOT(ISNUMBER($H10)),NOT(ISNUMBER($I10)),NOT(ISNUMBER($G10))),"",IF(OR($AG10="",$AH10=""),"",IF(ROUND(ABS($H10-$I10)*ABS($G10)*$AG10*$AH10,6)=0,"",ROUND(ABS($H10-$I10)*ABS($G10)*$AG10*$AH10,6)))) -> 30 | W10: =IF($AM10=0,"",IF($BG10="","OK",LEFT($BG10,LEN($BG10)-2))) -> OK | X10: US | Y10: Breakout & Retest | Z10: Yes | AA10: Calm | AC10: Reclaimed 64k and held | AD10: Clean. | AF10: =IF($AM10=0,"",IF($D10<>"",$D10,IF(IFERROR(INDEX(Accounts!$C$7:$C$16,MATCH($C10,Accounts!$B$7:$B$16,0))&"","")<>"",INDEX(Accounts!$C$7:$C$16,MATCH($C10,Accounts!$B$7:$B$16,0)),Settings!$C$6))) -> Crypto | AG10: =IF($AM10=0,"",IF(AND($BE10>0,N(INDEX(Instruments!$D$6:$D$205,MAX(1,$BE10)))>0),INDEX(Instruments!$D$6:$D$205,MAX(1,$BE10)),IF(N(INDEX(Settings!$D$14:$D$18,$BF10))>0,INDEX(Settings!$D$14:$D$18,$BF10),""))) -> 1 | AH10: =IF($AM10=0,"",IF($AF10<>"Forex",1,IF(MID(UPPER(SUBSTITUTE(TRIM($E10),"/","")),4,3)=UPPER(TRIM(Settings!$C$7)),1,IF(LEFT(UPPER(SUBSTITUTE(TRIM($E10),"/","")),3)=UPPER(TRIM(Settings!$C$7)),IF(AND(ISNUMBER($K10),N($K10)<>0),1/$K10,""),"")))) -> 1 | AI10: =IF($AM10=0,"",IF(OR(NOT(ISNUMBER($H10)),NOT(ISNUMBER($K10)),NOT(ISNUMBER($G10)),$AG10="",$AH10=""),"",ROUND(($K10-$H10)*IF($F10="Short",-1,1)*$G10*$AG10*$AH10,6))) -> 60 | AJ10: =IF($AM10=0,"",IF(INDEX(Settings!$E$14:$E$18,$BF10)="% of notional",IF(OR($AG10="",NOT(ISNUMBER($H10)),NOT(ISNUMBER($G10))),"",ROUND(ABS($H10*$G10*$AG10*N($AH10))*IF($L10="Limit",N(INDEX(Settings!$G$14:$G$18,$BF10)),N(INDEX(Settings!$H$14:$H$18,$BF10)))+IF(ISNUMBER($K10),ABS($K10*$G10*$AG10*N($AH10))*IF($M10="Target",N(INDEX(Settings!$G$14:$G$18,$BF10)),N(INDEX(Settings!$H$14:$H$18,$BF10))),0),6)),IF(NOT(ISNUMBER($G10)),"",ROUND(ABS($G10)*2*IF(AND($BE10>0,ISNUMBER(INDEX(Instruments!$G$6:$G$205,MAX(1,$BE10)))),INDEX(Instruments!$G$6:$G$205,MAX(1,$BE10)),N(INDEX(Settings!$F$14:$F$18,$BF10))),6)))) -> 1.296 | AK10: =IF($AM10=0,"",IF(ISNUMBER($O10),$O10,$AI10)) -> 60 | AL10: =IF($AM10=0,"",IF(ISNUMBER($P10),$P10,N($AJ10))) -> 1.296 | AM10: =IF(AND($A10<>"",$E10<>"",OR(AND(ISNUMBER($G10),ISNUMBER($H10),ISNUMBER($K10)),ISNUMBER($O10))),1,0) -> 1 | AN10: =IF($A10="","",$A10-WEEKDAY($A10,3)) -> 46286 | AO10: =IF($A10="","",WEEKDAY($A10,2)) -> 2 | AP10: =IF(OR($AM10=0,$C10=""),"",IFERROR(N(INDEX(Accounts!$E$7:$E$16,MATCH($C10,Accounts!$B$7:$B$16,0))),0)+SUMIFS($Q$6:$Q10,$C$6:$C10,$C10)) -> 5058.704 | AQ10: =IF(OR($AM10=0,$C10=""),"",SUMIFS($Q$6:$Q$1005,$C$6:$C$1005,$C10,$A$6:$A$1005,$A10)) -> 58.704 | AR10: =IF(OR($AM10=0,$C10=""),"",IFERROR(N(INDEX(Accounts!$E$7:$E$16,MATCH($C10,Accounts!$B$7:$B$16,0))),0)+SUMIFS($Q$6:$Q$1005,$C$6:$C$1005,$C10,$A$6:$A$1005,"<="&$A10)) -> 5058.704 | AS10: =IF(OR($AM10=0,$Q10=""),0,IF(AND($A10>=Lists!$W$6,$A10<=Lists!$W$7,OR(Dashboard!$D$6="All accounts",$C10=Dashboard!$D$6),OR(Dashboard!$D$7="All markets",$AF10=Dashboard!$D$7)),1,0)) -> 1 | AT10: =IF($AS10=1,N(AT9)+$Q10,N(AT9)) -> 414.204 | AU10: =MAX(N(AU9),$AT10) -> 417.5 | AV10: =$AT10-$AU10 -> -3.296 | AW10: =IF($AS10=1,IF($S10="Win",N(AW9)+1,IF($S10="Loss",0,N(AW9))),N(AW9)) -> 1 | AX10: =IF($AS10=1,IF($S10="Loss",N(AX9)+1,IF($S10="Win",0,N(AX9))),N(AX9)) -> 0 | AY10: =IF($AS10=1,COUNTIF($AS$6:$AS10,1),"") -> 5 | AZ10: =MIN(4,N(Lists!$W$8)) -> 4 | BA10: =IF($AS10=1,IF(COUNTIFS($A$6:$A10,$A10,$AS$6:$AS10,1)=1,1,0),0) -> 0 | BB10: =IF($BA10=1,SUMIFS($Q$6:$Q$1005,$A$6:$A$1005,$A10,$AS$6:$AS$1005,1),"") | BC10: =IF(ISNUMBER($R10),1,0) -> 1 | BD10: =IF(ISNUMBER($U10),$U10*$V10,"") -> 0 | BE10: =IF($AM10=0,"",IFERROR(MATCH($AF10&"|"&UPPER(TRIM($E10)),Lists!$A$6:$A$205,0),0)) -> 46 | BF10: =IF($AM10=0,"",IFERROR(MATCH($AF10,Settings!$B$14:$B$18,0),IFERROR(MATCH(Settings!$C$6,Settings!$B$14:$B$18,0),1))) -> 5 | BG10: =IF($AM10=0,"",IF(NOT(ISNUMBER($I10)),"No stop; ","")&IF(AND(ISNUMBER($H10),ISNUMBER($I10)),IF(OR(AND($F10<>"Short",$I10>=$H10),AND($F10="Short",$I10<=$H10)),"Stop on wrong side; ",""),"")&IF($F10="","No direction; ","")&IF(AND(ISNUMBER(Settings!$C$22),ISNUMBER($V10)),IF($V10>Settings!$C$22,"Risk over max $; ",""),"")&IF(AND(ISNUMBER(Settings!$C$23),ISNUMBER($V10),ISNUMBER($AP10),IFERROR(N(INDEX(Accounts!$E$7:$E$16,MATCH($C10,Accounts!$B$7:$B$16,0))),0)>0),IF($V10>Settings!$C$23*($AP10-N($Q10)),"Risk over max %; ",""),"")&IF(AND(ISNUMBER(Settings!$C$24),ISNUMBER($N10)),IF($N10>Settings!$C$24,"Leverage over max; ",""),"")&IF(AND(ISNUMBER(Settings!$C$27),ISNUMBER($T10)),IF($T10<Settings!$C$27,"R:R below min; ",""),"")&IF(ISNUMBER(Settings!$C$25),IF(COUNTIFS($A$6:$A10,$A10,$AM$6:$AM10,1)>Settings!$C$25,"Over max trades/day; ",""),"")&IF(ISNUMBER(Settings!$C$26),IF(SUMIFS($Q$5:$Q9,$A$5:$A9,$A10)<=-Settings!$C$26,"Traded after daily max loss; ",""),"")&IF(AND($AG10="",NOT(ISNUMBER($O10))),"Symbol not in Instruments; ","")&IF(AND($AH10="",NOT(ISNUMBER($O10))),"Forex cross: type Gross P&L; ","")) | BH10: =IF(ISNUMBER($Q10),1,0) -> 1 | BI10: =IF($Y10="",0,1) -> 1 | BJ10: =IF($AB10="",0,1) -> 0 | BK10: =IF(AND($BH10=1,$W10<>"OK"),1,0) -> 0 | BL10: =IF(N($AZ10)=0,0,IFERROR(INDEX($AT$6:$AT$1005,MATCH($AZ10,$AY$6:$AY$1005,0)),0)) -> 355.5 | BM10: =IF(ISNUMBER(SEARCH("daily max loss",$BG10)),1,0) -> 0
A11: 46288 | B11: 0.40833333 | C11: Prop Eval 50K | E11: MNQ | F11: Short | G11: 1 | H11: 29815 | I11: 29845 | J11: 29755 | K11: 29757.5 | L11: Limit | M11: Manual | Q11: =IF($AM11=0,"",IF(ISNUMBER($AK11),$AK11-N($AL11),"")) -> 114 | R11: =IF(OR($Q11="",NOT(ISNUMBER($V11))),"",$AK11/$V11) -> 1.9166667 | S11: =IF($Q11="","",IF(AND(ISNUMBER($R11),ABS(N($R11))<N(Settings!$C$8)),"Scratch",IF($Q11>0,"Win",IF($Q11<0,"Loss","Scratch")))) -> Win | T11: =IF(OR($AM11=0,NOT(ISNUMBER($H11)),NOT(ISNUMBER($I11)),NOT(ISNUMBER($J11))),"",IF($H11=$I11,"",ROUND(ABS($J11-$H11)/ABS($H11-$I11),6))) -> 2 | U11: =IF(OR($S11<>"Win",NOT(ISNUMBER($T11)),NOT(ISNUMBER($R11))),"",MAX(0,$T11-$R11)) -> 0.083333333 | V11: =IF(OR($AM11=0,NOT(ISNUMBER($H11)),NOT(ISNUMBER($I11)),NOT(ISNUMBER($G11))),"",IF(OR($AG11="",$AH11=""),"",IF(ROUND(ABS($H11-$I11)*ABS($G11)*$AG11*$AH11,6)=0,"",ROUND(ABS($H11-$I11)*ABS($G11)*$AG11*$AH11,6)))) -> 60 | W11: =IF($AM11=0,"",IF($BG11="","OK",LEFT($BG11,LEN($BG11)-2))) -> OK | X11: NY Open | Y11: Range Fade | Z11: Yes | AA11: Confident | AC11: Faded the top of a 2-day range | AD11: Closed 2 ticks before target. Fine. | AF11: =IF($AM11=0,"",IF($D11<>"",$D11,IF(IFERROR(INDEX(Accounts!$C$7:$C$16,MATCH($C11,Accounts!$B$7:$B$16,0))&"","")<>"",INDEX(Accounts!$C$7:$C$16,MATCH($C11,Accounts!$B$7:$B$16,0)),Settings!$C$6))) -> Futures | AG11: =IF($AM11=0,"",IF(AND($BE11>0,N(INDEX(Instruments!$D$6:$D$205,MAX(1,$BE11)))>0),INDEX(Instruments!$D$6:$D$205,MAX(1,$BE11)),IF(N(INDEX(Settings!$D$14:$D$18,$BF11))>0,INDEX(Settings!$D$14:$D$18,$BF11),""))) -> 2 | AH11: =IF($AM11=0,"",IF($AF11<>"Forex",1,IF(MID(UPPER(SUBSTITUTE(TRIM($E11),"/","")),4,3)=UPPER(TRIM(Settings!$C$7)),1,IF(LEFT(UPPER(SUBSTITUTE(TRIM($E11),"/","")),3)=UPPER(TRIM(Settings!$C$7)),IF(AND(ISNUMBER($K11),N($K11)<>0),1/$K11,""),"")))) -> 1 | AI11: =IF($AM11=0,"",IF(OR(NOT(ISNUMBER($H11)),NOT(ISNUMBER($K11)),NOT(ISNUMBER($G11)),$AG11="",$AH11=""),"",ROUND(($K11-$H11)*IF($F11="Short",-1,1)*$G11*$AG11*$AH11,6))) -> 115 | AJ11: =IF($AM11=0,"",IF(INDEX(Settings!$E$14:$E$18,$BF11)="% of notional",IF(OR($AG11="",NOT(ISNUMBER($H11)),NOT(ISNUMBER($G11))),"",ROUND(ABS($H11*$G11*$AG11*N($AH11))*IF($L11="Limit",N(INDEX(Settings!$G$14:$G$18,$BF11)),N(INDEX(Settings!$H$14:$H$18,$BF11)))+IF(ISNUMBER($K11),ABS($K11*$G11*$AG11*N($AH11))*IF($M11="Target",N(INDEX(Settings!$G$14:$G$18,$BF11)),N(INDEX(Settings!$H$14:$H$18,$BF11))),0),6)),IF(NOT(ISNUMBER($G11)),"",ROUND(ABS($G11)*2*IF(AND($BE11>0,ISNUMBER(INDEX(Instruments!$G$6:$G$205,MAX(1,$BE11)))),INDEX(Instruments!$G$6:$G$205,MAX(1,$BE11)),N(INDEX(Settings!$F$14:$F$18,$BF11))),6)))) -> 1 | AK11: =IF($AM11=0,"",IF(ISNUMBER($O11),$O11,$AI11)) -> 115 | AL11: =IF($AM11=0,"",IF(ISNUMBER($P11),$P11,N($AJ11))) -> 1 | AM11: =IF(AND($A11<>"",$E11<>"",OR(AND(ISNUMBER($G11),ISNUMBER($H11),ISNUMBER($K11)),ISNUMBER($O11))),1,0) -> 1 | AN11: =IF($A11="","",$A11-WEEKDAY($A11,3)) -> 46286 | AO11: =IF($A11="","",WEEKDAY($A11,2)) -> 3 | AP11: =IF(OR($AM11=0,$C11=""),"",IFERROR(N(INDEX(Accounts!$E$7:$E$16,MATCH($C11,Accounts!$B$7:$B$16,0))),0)+SUMIFS($Q$6:$Q11,$C$6:$C11,$C11)) -> 50469.5 | AQ11: =IF(OR($AM11=0,$C11=""),"",SUMIFS($Q$6:$Q$1005,$C$6:$C$1005,$C11,$A$6:$A$1005,$A11)) -> 6 | AR11: =IF(OR($AM11=0,$C11=""),"",IFERROR(N(INDEX(Accounts!$E$7:$E$16,MATCH($C11,Accounts!$B$7:$B$16,0))),0)+SUMIFS($Q$6:$Q$1005,$C$6:$C$1005,$C11,$A$6:$A$1005,"<="&$A11)) -> 50361.5 | AS11: =IF(OR($AM11=0,$Q11=""),0,IF(AND($A11>=Lists!$W$6,$A11<=Lists!$W$7,OR(Dashboard!$D$6="All accounts",$C11=Dashboard!$D$6),OR(Dashboard!$D$7="All markets",$AF11=Dashboard!$D$7)),1,0)) -> 1 | AT11: =IF($AS11=1,N(AT10)+$Q11,N(AT10)) -> 528.204 | AU11: =MAX(N(AU10),$AT11) -> 528.204 | AV11: =$AT11-$AU11 -> 0 | AW11: =IF($AS11=1,IF($S11="Win",N(AW10)+1,IF($S11="Loss",0,N(AW10))),N(AW10)) -> 2 | AX11: =IF($AS11=1,IF($S11="Loss",N(AX10)+1,IF($S11="Win",0,N(AX10))),N(AX10)) -> 0 | AY11: =IF($AS11=1,COUNTIF($AS$6:$AS11,1),"") -> 6 | AZ11: =MIN(5,N(Lists!$W$8)) -> 5 | BA11: =IF($AS11=1,IF(COUNTIFS($A$6:$A11,$A11,$AS$6:$AS11,1)=1,1,0),0) -> 1 | BB11: =IF($BA11=1,SUMIFS($Q$6:$Q$1005,$A$6:$A$1005,$A11,$AS$6:$AS$1005,1),"") -> 6 | BC11: =IF(ISNUMBER($R11),1,0) -> 1 | BD11: =IF(ISNUMBER($U11),$U11*$V11,"") -> 5 | BE11: =IF($AM11=0,"",IFERROR(MATCH($AF11&"|"&UPPER(TRIM($E11)),Lists!$A$6:$A$205,0),0)) -> 3 | BF11: =IF($AM11=0,"",IFERROR(MATCH($AF11,Settings!$B$14:$B$18,0),IFERROR(MATCH(Settings!$C$6,Settings!$B$14:$B$18,0),1))) -> 1 | BG11: =IF($AM11=0,"",IF(NOT(ISNUMBER($I11)),"No stop; ","")&IF(AND(ISNUMBER($H11),ISNUMBER($I11)),IF(OR(AND($F11<>"Short",$I11>=$H11),AND($F11="Short",$I11<=$H11)),"Stop on wrong side; ",""),"")&IF($F11="","No direction; ","")&IF(AND(ISNUMBER(Settings!$C$22),ISNUMBER($V11)),IF($V11>Settings!$C$22,"Risk over max $; ",""),"")&IF(AND(ISNUMBER(Settings!$C$23),ISNUMBER($V11),ISNUMBER($AP11),IFERROR(N(INDEX(Accounts!$E$7:$E$16,MATCH($C11,Accounts!$B$7:$B$16,0))),0)>0),IF($V11>Settings!$C$23*($AP11-N($Q11)),"Risk over max %; ",""),"")&IF(AND(ISNUMBER(Settings!$C$24),ISNUMBER($N11)),IF($N11>Settings!$C$24,"Leverage over max; ",""),"")&IF(AND(ISNUMBER(Settings!$C$27),ISNUMBER($T11)),IF($T11<Settings!$C$27,"R:R below min; ",""),"")&IF(ISNUMBER(Settings!$C$25),IF(COUNTIFS($A$6:$A11,$A11,$AM$6:$AM11,1)>Settings!$C$25,"Over max trades/day; ",""),"")&IF(ISNUMBER(Settings!$C$26),IF(SUMIFS($Q$5:$Q10,$A$5:$A10,$A11)<=-Settings!$C$26,"Traded after daily max loss; ",""),"")&IF(AND($AG11="",NOT(ISNUMBER($O11))),"Symbol not in Instruments; ","")&IF(AND($AH11="",NOT(ISNUMBER($O11))),"Forex cross: type Gross P&L; ","")) | BH11: =IF(ISNUMBER($Q11),1,0) -> 1 | BI11: =IF($Y11="",0,1) -> 1 | BJ11: =IF($AB11="",0,1) -> 0 | BK11: =IF(AND($BH11=1,$W11<>"OK"),1,0) -> 0 | BL11: =IF(N($AZ11)=0,0,IFERROR(INDEX($AT$6:$AT$1005,MATCH($AZ11,$AY$6:$AY$1005,0)),0)) -> 414.204 | BM11: =IF(ISNUMBER(SEARCH("daily max loss",$BG11)),1,0) -> 0
A12: 46288 | B12: 0.55555556 | C12: Prop Eval 50K | E12: MES | F12: Long | G12: 3 | H12: 7690 | I12: 7683 | J12: 7704 | K12: 7683 | L12: Market | M12: Stop loss | Q12: =IF($AM12=0,"",IF(ISNUMBER($AK12),$AK12-N($AL12),"")) -> -108 | R12: =IF(OR($Q12="",NOT(ISNUMBER($V12))),"",$AK12/$V12) -> -1 | S12: =IF($Q12="","",IF(AND(ISNUMBER($R12),ABS(N($R12))<N(Settings!$C$8)),"Scratch",IF($Q12>0,"Win",IF($Q12<0,"Loss","Scratch")))) -> Loss | T12: =IF(OR($AM12=0,NOT(ISNUMBER($H12)),NOT(ISNUMBER($I12)),NOT(ISNUMBER($J12))),"",IF($H12=$I12,"",ROUND(ABS($J12-$H12)/ABS($H12-$I12),6))) -> 2 | U12: =IF(OR($S12<>"Win",NOT(ISNUMBER($T12)),NOT(ISNUMBER($R12))),"",MAX(0,$T12-$R12)) | V12: =IF(OR($AM12=0,NOT(ISNUMBER($H12)),NOT(ISNUMBER($I12)),NOT(ISNUMBER($G12))),"",IF(OR($AG12="",$AH12=""),"",IF(ROUND(ABS($H12-$I12)*ABS($G12)*$AG12*$AH12,6)=0,"",ROUND(ABS($H12-$I12)*ABS($G12)*$AG12*$AH12,6)))) -> 105 | W12: =IF($AM12=0,"",IF($BG12="","OK",LEFT($BG12,LEN($BG12)-2))) -> OK | X12: NY Afternoon | Z12: No | AA12: Bored | AB12: No setup (impulse) | AC12: Chop. Wanted action. | AD12: No setup. Should have walked away. | AF12: =IF($AM12=0,"",IF($D12<>"",$D12,IF(IFERROR(INDEX(Accounts!$C$7:$C$16,MATCH($C12,Accounts!$B$7:$B$16,0))&"","")<>"",INDEX(Accounts!$C$7:$C$16,MATCH($C12,Accounts!$B$7:$B$16,0)),Settings!$C$6))) -> Futures | AG12: =IF($AM12=0,"",IF(AND($BE12>0,N(INDEX(Instruments!$D$6:$D$205,MAX(1,$BE12)))>0),INDEX(Instruments!$D$6:$D$205,MAX(1,$BE12)),IF(N(INDEX(Settings!$D$14:$D$18,$BF12))>0,INDEX(Settings!$D$14:$D$18,$BF12),""))) -> 5 | AH12: =IF($AM12=0,"",IF($AF12<>"Forex",1,IF(MID(UPPER(SUBSTITUTE(TRIM($E12),"/","")),4,3)=UPPER(TRIM(Settings!$C$7)),1,IF(LEFT(UPPER(SUBSTITUTE(TRIM($E12),"/","")),3)=UPPER(TRIM(Settings!$C$7)),IF(AND(ISNUMBER($K12),N($K12)<>0),1/$K12,""),"")))) -> 1 | AI12: =IF($AM12=0,"",IF(OR(NOT(ISNUMBER($H12)),NOT(ISNUMBER($K12)),NOT(ISNUMBER($G12)),$AG12="",$AH12=""),"",ROUND(($K12-$H12)*IF($F12="Short",-1,1)*$G12*$AG12*$AH12,6))) -> -105 | AJ12: =IF($AM12=0,"",IF(INDEX(Settings!$E$14:$E$18,$BF12)="% of notional",IF(OR($AG12="",NOT(ISNUMBER($H12)),NOT(ISNUMBER($G12))),"",ROUND(ABS($H12*$G12*$AG12*N($AH12))*IF($L12="Limit",N(INDEX(Settings!$G$14:$G$18,$BF12)),N(INDEX(Settings!$H$14:$H$18,$BF12)))+IF(ISNUMBER($K12),ABS($K12*$G12*$AG12*N($AH12))*IF($M12="Target",N(INDEX(Settings!$G$14:$G$18,$BF12)),N(INDEX(Settings!$H$14:$H$18,$BF12))),0),6)),IF(NOT(ISNUMBER($G12)),"",ROUND(ABS($G12)*2*IF(AND($BE12>0,ISNUMBER(INDEX(Instruments!$G$6:$G$205,MAX(1,$BE12)))),INDEX(Instruments!$G$6:$G$205,MAX(1,$BE12)),N(INDEX(Settings!$F$14:$F$18,$BF12))),6)))) -> 3 | AK12: =IF($AM12=0,"",IF(ISNUMBER($O12),$O12,$AI12)) -> -105 | AL12: =IF($AM12=0,"",IF(ISNUMBER($P12),$P12,N($AJ12))) -> 3 | AM12: =IF(AND($A12<>"",$E12<>"",OR(AND(ISNUMBER($G12),ISNUMBER($H12),ISNUMBER($K12)),ISNUMBER($O12))),1,0) -> 1 | AN12: =IF($A12="","",$A12-WEEKDAY($A12,3)) -> 46286 | AO12: =IF($A12="","",WEEKDAY($A12,2)) -> 3 | AP12: =IF(OR($AM12=0,$C12=""),"",IFERROR(N(INDEX(Accounts!$E$7:$E$16,MATCH($C12,Accounts!$B$7:$B$16,0))),0)+SUMIFS($Q$6:$Q12,$C$6:$C12,$C12)) -> 50361.5 | AQ12: =IF(OR($AM12=0,$C12=""),"",SUMIFS($Q$6:$Q$1005,$C$6:$C$1005,$C12,$A$6:$A$1005,$A12)) -> 6 | AR12: =IF(OR($AM12=0,$C12=""),"",IFERROR(N(INDEX(Accounts!$E$7:$E$16,MATCH($C12,Accounts!$B$7:$B$16,0))),0)+SUMIFS($Q$6:$Q$1005,$C$6:$C$1005,$C12,$A$6:$A$1005,"<="&$A12)) -> 50361.5 | AS12: =IF(OR($AM12=0,$Q12=""),0,IF(AND($A12>=Lists!$W$6,$A12<=Lists!$W$7,OR(Dashboard!$D$6="All accounts",$C12=Dashboard!$D$6),OR(Dashboard!$D$7="All markets",$AF12=Dashboard!$D$7)),1,0)) -> 1 | AT12: =IF($AS12=1,N(AT11)+$Q12,N(AT11)) -> 420.204 | AU12: =MAX(N(AU11),$AT12) -> 528.204 | AV12: =$AT12-$AU12 -> -108 | AW12: =IF($AS12=1,IF($S12="Win",N(AW11)+1,IF($S12="Loss",0,N(AW11))),N(AW11)) -> 0 | AX12: =IF($AS12=1,IF($S12="Loss",N(AX11)+1,IF($S12="Win",0,N(AX11))),N(AX11)) -> 1 | AY12: =IF($AS12=1,COUNTIF($AS$6:$AS12,1),"") -> 7 | AZ12: =MIN(6,N(Lists!$W$8)) -> 6 | BA12: =IF($AS12=1,IF(COUNTIFS($A$6:$A12,$A12,$AS$6:$AS12,1)=1,1,0),0) -> 0 | BB12: =IF($BA12=1,SUMIFS($Q$6:$Q$1005,$A$6:$A$1005,$A12,$AS$6:$AS$1005,1),"") | BC12: =IF(ISNUMBER($R12),1,0) -> 1 | BD12: =IF(ISNUMBER($U12),$U12*$V12,"") | BE12: =IF($AM12=0,"",IFERROR(MATCH($AF12&"|"&UPPER(TRIM($E12)),Lists!$A$6:$A$205,0),0)) -> 1 | BF12: =IF($AM12=0,"",IFERROR(MATCH($AF12,Settings!$B$14:$B$18,0),IFERROR(MATCH(Settings!$C$6,Settings!$B$14:$B$18,0),1))) -> 1 | BG12: =IF($AM12=0,"",IF(NOT(ISNUMBER($I12)),"No stop; ","")&IF(AND(ISNUMBER($H12),ISNUMBER($I12)),IF(OR(AND($F12<>"Short",$I12>=$H12),AND($F12="Short",$I12<=$H12)),"Stop on wrong side; ",""),"")&IF($F12="","No direction; ","")&IF(AND(ISNUMBER(Settings!$C$22),ISNUMBER($V12)),IF($V12>Settings!$C$22,"Risk over max $; ",""),"")&IF(AND(ISNUMBER(Settings!$C$23),ISNUMBER($V12),ISNUMBER($AP12),IFERROR(N(INDEX(Accounts!$E$7:$E$16,MATCH($C12,Accounts!$B$7:$B$16,0))),0)>0),IF($V12>Settings!$C$23*($AP12-N($Q12)),"Risk over max %; ",""),"")&IF(AND(ISNUMBER(Settings!$C$24),ISNUMBER($N12)),IF($N12>Settings!$C$24,"Leverage over max; ",""),"")&IF(AND(ISNUMBER(Settings!$C$27),ISNUMBER($T12)),IF($T12<Settings!$C$27,"R:R below min; ",""),"")&IF(ISNUMBER(Settings!$C$25),IF(COUNTIFS($A$6:$A12,$A12,$AM$6:$AM12,1)>Settings!$C$25,"Over max trades/day; ",""),"")&IF(ISNUMBER(Settings!$C$26),IF(SUMIFS($Q$5:$Q11,$A$5:$A11,$A12)<=-Settings!$C$26,"Traded after daily max loss; ",""),"")&IF(AND($AG12="",NOT(ISNUMBER($O12))),"Symbol not in Instruments; ","")&IF(AND($AH12="",NOT(ISNUMBER($O12))),"Forex cross: type Gross P&L; ","")) | BH12: =IF(ISNUMBER($Q12),1,0) -> 1 | BI12: =IF($Y12="",0,1) -> 0 | BJ12: =IF($AB12="",0,1) -> 1 | BK12: =IF(AND($BH12=1,$W12<>"OK"),1,0) -> 0 | BL12: =IF(N($AZ12)=0,0,IFERROR(INDEX($AT$6:$AT$1005,MATCH($AZ12,$AY$6:$AY$1005,0)),0)) -> 528.204 | BM12: =IF(ISNUMBER(SEARCH("daily max loss",$BG12)),1,0) -> 0
A13: 46289 | B13: 0.39930556 | C13: Prop Eval 50K | E13: SIL | F13: Long | G13: 1 | H13: 51.2 | I13: 51.05 | J13: 51.5 | K13: 51.5 | L13: Limit | M13: Target | Q13: =IF($AM13=0,"",IF(ISNUMBER($AK13),$AK13-N($AL13),"")) -> 299 | R13: =IF(OR($Q13="",NOT(ISNUMBER($V13))),"",$AK13/$V13) -> 2 | S13: =IF($Q13="","",IF(AND(ISNUMBER($R13),ABS(N($R13))<N(Settings!$C$8)),"Scratch",IF($Q13>0,"Win",IF($Q13<0,"Loss","Scratch")))) -> Win | T13: =IF(OR($AM13=0,NOT(ISNUMBER($H13)),NOT(ISNUMBER($I13)),NOT(ISNUMBER($J13))),"",IF($H13=$I13,"",ROUND(ABS($J13-$H13)/ABS($H13-$I13),6))) -> 2 | U13: =IF(OR($S13<>"Win",NOT(ISNUMBER($T13)),NOT(ISNUMBER($R13))),"",MAX(0,$T13-$R13)) -> 0 | V13: =IF(OR($AM13=0,NOT(ISNUMBER($H13)),NOT(ISNUMBER($I13)),NOT(ISNUMBER($G13))),"",IF(OR($AG13="",$AH13=""),"",IF(ROUND(ABS($H13-$I13)*ABS($G13)*$AG13*$AH13,6)=0,"",ROUND(ABS($H13-$I13)*ABS($G13)*$AG13*$AH13,6)))) -> 150 | W13: =IF($AM13=0,"",IF($BG13="","OK",LEFT($BG13,LEN($BG13)-2))) -> OK | X13: NY Open | Y13: Trend Pullback | Z13: Yes | AA13: Calm | AC13: Silver pulled back to VWAP in an uptrend | AD13: Patient entry, held to target. | AF13: =IF($AM13=0,"",IF($D13<>"",$D13,IF(IFERROR(INDEX(Accounts!$C$7:$C$16,MATCH($C13,Accounts!$B$7:$B$16,0))&"","")<>"",INDEX(Accounts!$C$7:$C$16,MATCH($C13,Accounts!$B$7:$B$16,0)),Settings!$C$6))) -> Futures | AG13: =IF($AM13=0,"",IF(AND($BE13>0,N(INDEX(Instruments!$D$6:$D$205,MAX(1,$BE13)))>0),INDEX(Instruments!$D$6:$D$205,MAX(1,$BE13)),IF(N(INDEX(Settings!$D$14:$D$18,$BF13))>0,INDEX(Settings!$D$14:$D$18,$BF13),""))) -> 1000 | AH13: =IF($AM13=0,"",IF($AF13<>"Forex",1,IF(MID(UPPER(SUBSTITUTE(TRIM($E13),"/","")),4,3)=UPPER(TRIM(Settings!$C$7)),1,IF(LEFT(UPPER(SUBSTITUTE(TRIM($E13),"/","")),3)=UPPER(TRIM(Settings!$C$7)),IF(AND(ISNUMBER($K13),N($K13)<>0),1/$K13,""),"")))) -> 1 | AI13: =IF($AM13=0,"",IF(OR(NOT(ISNUMBER($H13)),NOT(ISNUMBER($K13)),NOT(ISNUMBER($G13)),$AG13="",$AH13=""),"",ROUND(($K13-$H13)*IF($F13="Short",-1,1)*$G13*$AG13*$AH13,6))) -> 300 | AJ13: =IF($AM13=0,"",IF(INDEX(Settings!$E$14:$E$18,$BF13)="% of notional",IF(OR($AG13="",NOT(ISNUMBER($H13)),NOT(ISNUMBER($G13))),"",ROUND(ABS($H13*$G13*$AG13*N($AH13))*IF($L13="Limit",N(INDEX(Settings!$G$14:$G$18,$BF13)),N(INDEX(Settings!$H$14:$H$18,$BF13)))+IF(ISNUMBER($K13),ABS($K13*$G13*$AG13*N($AH13))*IF($M13="Target",N(INDEX(Settings!$G$14:$G$18,$BF13)),N(INDEX(Settings!$H$14:$H$18,$BF13))),0),6)),IF(NOT(ISNUMBER($G13)),"",ROUND(ABS($G13)*2*IF(AND($BE13>0,ISNUMBER(INDEX(Instruments!$G$6:$G$205,MAX(1,$BE13)))),INDEX(Instruments!$G$6:$G$205,MAX(1,$BE13)),N(INDEX(Settings!$F$14:$F$18,$BF13))),6)))) -> 1 | AK13: =IF($AM13=0,"",IF(ISNUMBER($O13),$O13,$AI13)) -> 300 | AL13: =IF($AM13=0,"",IF(ISNUMBER($P13),$P13,N($AJ13))) -> 1 | AM13: =IF(AND($A13<>"",$E13<>"",OR(AND(ISNUMBER($G13),ISNUMBER($H13),ISNUMBER($K13)),ISNUMBER($O13))),1,0) -> 1 | AN13: =IF($A13="","",$A13-WEEKDAY($A13,3)) -> 46286 | AO13: =IF($A13="","",WEEKDAY($A13,2)) -> 4 | AP13: =IF(OR($AM13=0,$C13=""),"",IFERROR(N(INDEX(Accounts!$E$7:$E$16,MATCH($C13,Accounts!$B$7:$B$16,0))),0)+SUMIFS($Q$6:$Q13,$C$6:$C13,$C13)) -> 50660.5 | AQ13: =IF(OR($AM13=0,$C13=""),"",SUMIFS($Q$6:$Q$1005,$C$6:$C$1005,$C13,$A$6:$A$1005,$A13)) -> 397 | AR13: =IF(OR($AM13=0,$C13=""),"",IFERROR(N(INDEX(Accounts!$E$7:$E$16,MATCH($C13,Accounts!$B$7:$B$16,0))),0)+SUMIFS($Q$6:$Q$1005,$C$6:$C$1005,$C13,$A$6:$A$1005,"<="&$A13)) -> 50758.5 | AS13: =IF(OR($AM13=0,$Q13=""),0,IF(AND($A13>=Lists!$W$6,$A13<=Lists!$W$7,OR(Dashboard!$D$6="All accounts",$C13=Dashboard!$D$6),OR(Dashboard!$D$7="All markets",$AF13=Dashboard!$D$7)),1,0)) -> 1 | AT13: =IF($AS13=1,N(AT12)+$Q13,N(AT12)) -> 719.204 | AU13: =MAX(N(AU12),$AT13) -> 719.204 | AV13: =$AT13-$AU13 -> 0 | AW13: =IF($AS13=1,IF($S13="Win",N(AW12)+1,IF($S13="Loss",0,N(AW12))),N(AW12)) -> 1 | AX13: =IF($AS13=1,IF($S13="Loss",N(AX12)+1,IF($S13="Win",0,N(AX12))),N(AX12)) -> 0 | AY13: =IF($AS13=1,COUNTIF($AS$6:$AS13,1),"") -> 8 | AZ13: =MIN(7,N(Lists!$W$8)) -> 7 | BA13: =IF($AS13=1,IF(COUNTIFS($A$6:$A13,$A13,$AS$6:$AS13,1)=1,1,0),0) -> 1 | BB13: =IF($BA13=1,SUMIFS($Q$6:$Q$1005,$A$6:$A$1005,$A13,$AS$6:$AS$1005,1),"") -> 347.761 | BC13: =IF(ISNUMBER($R13),1,0) -> 1 | BD13: =IF(ISNUMBER($U13),$U13*$V13,"") -> 0 | BE13: =IF($AM13=0,"",IFERROR(MATCH($AF13&"|"&UPPER(TRIM($E13)),Lists!$A$6:$A$205,0),0)) -> 16 | BF13: =IF($AM13=0,"",IFERROR(MATCH($AF13,Settings!$B$14:$B$18,0),IFERROR(MATCH(Settings!$C$6,Settings!$B$14:$B$18,0),1))) -> 1 | BG13: =IF($AM13=0,"",IF(NOT(ISNUMBER($I13)),"No stop; ","")&IF(AND(ISNUMBER($H13),ISNUMBER($I13)),IF(OR(AND($F13<>"Short",$I13>=$H13),AND($F13="Short",$I13<=$H13)),"Stop on wrong side; ",""),"")&IF($F13="","No direction; ","")&IF(AND(ISNUMBER(Settings!$C$22),ISNUMBER($V13)),IF($V13>Settings!$C$22,"Risk over max $; ",""),"")&IF(AND(ISNUMBER(Settings!$C$23),ISNUMBER($V13),ISNUMBER($AP13),IFERROR(N(INDEX(Accounts!$E$7:$E$16,MATCH($C13,Accounts!$B$7:$B$16,0))),0)>0),IF($V13>Settings!$C$23*($AP13-N($Q13)),"Risk over max %; ",""),"")&IF(AND(ISNUMBER(Settings!$C$24),ISNUMBER($N13)),IF($N13>Settings!$C$24,"Leverage over max; ",""),"")&IF(AND(ISNUMBER(Settings!$C$27),ISNUMBER($T13)),IF($T13<Settings!$C$27,"R:R below min; ",""),"")&IF(ISNUMBER(Settings!$C$25),IF(COUNTIFS($A$6:$A13,$A13,$AM$6:$AM13,1)>Settings!$C$25,"Over max trades/day; ",""),"")&IF(ISNUMBER(Settings!$C$26),IF(SUMIFS($Q$5:$Q12,$A$5:$A12,$A13)<=-Settings!$C$26,"Traded after daily max loss; ",""),"")&IF(AND($AG13="",NOT(ISNUMBER($O13))),"Symbol not in Instruments; ","")&IF(AND($AH13="",NOT(ISNUMBER($O13))),"Forex cross: type Gross P&L; ","")) | BH13: =IF(ISNUMBER($Q13),1,0) -> 1 | BI13: =IF($Y13="",0,1) -> 1 | BJ13: =IF($AB13="",0,1) -> 0 | BK13: =IF(AND($BH13=1,$W13<>"OK"),1,0) -> 0 | BL13: =IF(N($AZ13)=0,0,IFERROR(INDEX($AT$6:$AT$1005,MATCH($AZ13,$AY$6:$AY$1005,0)),0)) -> 420.204 | BM13: =IF(ISNUMBER(SEARCH("daily max loss",$BG13)),1,0) -> 0
